Workbook

Sheet Cover
A9: UAA Baseline Cost Model Tables
A10: PARS Environment
A11: FY 25

Sheet Table 3.1-UAA Summary
B1: Table 3.1 - Summary of Costs for Processing Undeliverable-As-Addressed Mail
B2: PARS Environment, FY 25
B3: Activities Directly Associated with UAA Mail -- PARS Pieces
E4: Final Disposition
E5: Forwarded (1) | H5: Returned To Sender (2) | K5: Wasted (3)
E6: Cost | F6: Volume | G6: Unit | H6: Cost | I6: Volume | J6: Unit | K6: Cost | L6: Volume | M6: Unit
B7: Module | C7: Craft | D7: Activity | E7: ($000) | F7: (000) | G7: Cost | H7: ($000) | I7: (000) | J7: Cost | K7: ($000) | L7: (000) | M7: Cost
B8: Route | C8: Carrier/Clerk | D8: Identify/Separate | E8: =SUM('Table 3.3-PARS Fwd Summary'!F13) -> 7030.3672 | H8: =SUM('Table 3.6-PARS RTS Summary'!F21,'Table 3.6-PARS RTS Summary'!F31,'Table 3.6-PARS RTS Summary'!F52) -> 108976.51 | K8: =SUM('Table 3.9-PARS Wst Summary'!F21,'Table 3.9-PARS Wst Summary'!F39) -> 50806.099
B9: Nixie Unit | C9: Clerk | D9: Nixie Work (4) | E9: =SUM('Table 3.3-PARS Fwd Summary'!F14) -> 463.36451 | H9: =SUM('Table 3.6-PARS RTS Summary'!F9,'Table 3.6-PARS RTS Summary'!F22,'Table 3.6-PARS RTS Summary'!F32,'Table 3.6-PARS RTS Summary'!F37,'Table 3.6-PARS RTS Summary'!F53) -> 10016.544 | K9: =SUM('Table 3.9-PARS Wst Summary'!F9,'Table 3.9-PARS Wst Summary'!F22,'Table 3.9-PARS Wst Summary'!F40) -> 3389.2971
B10: CFS Unit | C10: Clerk | D10: Key/Label, Etc. (5) | E10: =SUM('Table 3.3-PARS Fwd Summary'!F9,'Table 3.3-PARS Fwd Summary'!F19) -> 1861.301 | H10: =SUM('Table 3.6-PARS RTS Summary'!F17,'Table 3.6-PARS RTS Summary'!F27,'Table 3.6-PARS RTS Summary'!F48,'Table 3.6-PARS RTS Summary'!F58) -> 1048.5865 | K10: =SUM('Table 3.9-PARS Wst Summary'!F17,'Table 3.9-PARS Wst Summary'!F27,'Table 3.9-PARS Wst Summary'!F35,'Table 3.9-PARS Wst Summary'!F45) -> 782.91892
B11: CIOSS | C11: Clerk/MH | D11: Image Lift/Label | E11: =SUM('Table 3.3-PARS Fwd Summary'!F5,'Table 3.3-PARS Fwd Summary'!F15) -> 18364.914 | H11: =SUM('Table 3.6-PARS RTS Summary'!F5,'Table 3.6-PARS RTS Summary'!F13,'Table 3.6-PARS RTS Summary'!F23,'Table 3.6-PARS RTS Summary'!F33,'Table 3.6-PARS RTS Summary'!F44,'Table 3.6-PARS RTS Summary'!F54) -> 30449.431 | K11: =SUM('Table 3.9-PARS Wst Summary'!F5,'Table 3.9-PARS Wst Summary'!F13,'Table 3.9-PARS Wst Summary'!F23,'Table 3.9-PARS Wst Summary'!F31,'Table 3.9-PARS Wst Summary'!F41) -> 30061.77
B12: REC Site | C12: Clerk | D12: Keying (5) | E12: =SUM('Table 3.3-PARS Fwd Summary'!F7:F8,'Table 3.3-PARS Fwd Summary'!F17:F18) -> 3047.9562 | H12: =SUM('Table 3.6-PARS RTS Summary'!F7:F8,'Table 3.6-PARS RTS Summary'!F15:F16,'Table 3.6-PARS RTS Summary'!F25:F26,'Table 3.6-PARS RTS Summary'!F35:F36,'Table 3.6-PARS RTS Summary'!F46:F47,'Table 3.6-PARS RTS Summary'!F56:F57) -> 15541.654 | K12: =SUM('Table 3.9-PARS Wst Summary'!F7:F8,'Table 3.9-PARS Wst Summary'!F15:F16,'Table 3.9-PARS Wst Summary'!F25:F26,'Table 3.9-PARS Wst Summary'!F33:F34,'Table 3.9-PARS Wst Summary'!F43:F44) -> 6238.3219
B13: Processing & Transport | C13: Clerk/MH | D13: Sort/Transport | E13: ='Table 3.3-PARS Fwd Summary'!F23 -> 58625.819 | H13: ='Table 3.6-PARS RTS Summary'!F62 -> 174256.09 | K13: 0
B14: Accountable Unit | C14: Carrier/Clerk | D14: Postage Due | E14: =SUM('Table 3.3-PARS Fwd Summary'!F24:F26) -> 0 | H14: =SUM('Table 3.6-PARS RTS Summary'!F63:F65) -> 4262.1686 | K14: 0
D15: Subtotal | E15: =SUM(E8:E14) -> 89393.722 | F15: ='Table 3.3-PARS Fwd Summary'!B29 -> 378308.29 | G15: =E15/F15 -> 0.23629861 | H15: =SUM(H8:H14) -> 344550.98 | I15: ='Table 3.6-PARS RTS Summary'!B68 -> 1124462.3 | J15: =H15/I15 -> 0.30641399 | K15: =SUM(K8:K14) -> 91278.407 | L15: ='Table 3.9-PARS Wst Summary'!B48 -> 846681.24 | M15: =K15/L15 -> 0.10780729
B17: Activities Directly Associated with UAA Mail -- Non-PARS Pieces
E18: Final Disposition
E19: Forwarded (6) | H19: Returned To Sender (7) | K19: Wasted (8)
E20: Cost | F20: Volume | G20: Unit | H20: Cost | I20: Volume | J20: Unit | K20: Cost | L20: Volume | M20: Unit
B21: Module | C21: Craft | D21: Activity | E21: ($000) | F21: (000) | G21: Cost | H21: ($000) | I21: (000) | J21: Cost | K21: ($000) | L21: (000) | M21: Cost
B22: Route | C22: Carrier/Clerk | D22: Identify/Separate | E22: =SUM('Table 3.4-NonPARS Fwd Summary'!F5,'Table 3.4-NonPARS Fwd Summary'!F11) -> 7369.6159 | H22: =SUM('Table 3.7-NonPARS RTS Summary'!F5,'Table 3.7-NonPARS RTS Summary'!F11,'Table 3.7-NonPARS RTS Summary'!F17) -> 14734.422 | K22: =SUM('Table 3.10-NonPARS Wst Summary'!F5,'Table 3.10-NonPARS Wst Summary'!F10,'Table 3.10-NonPARS Wst Summary'!F15) -> 69140.332
B23: Nixie Unit | C23: Clerk | D23: Nixie Work (4) | E23: =SUM('Table 3.4-NonPARS Fwd Summary'!F6:F7) -> 4624.3337 | H23: =SUM('Table 3.7-NonPARS RTS Summary'!F6:F7,'Table 3.7-NonPARS RTS Summary'!F18) -> 17151.682 | K23: =SUM('Table 3.10-NonPARS Wst Summary'!F6,'Table 3.10-NonPARS Wst Summary'!F16) -> 29245.187
B24: CFS Unit | C24: Clerk | D24: Key/Label, Etc. (5) | E24: =SUM('Table 3.4-NonPARS Fwd Summary'!F12:F13) -> 6597.6851 | H24: =SUM('Table 3.7-NonPARS RTS Summary'!F12:F13,'Table 3.7-NonPARS RTS Summary'!F19) -> 22219.493 | K24: =SUM('Table 3.10-NonPARS Wst Summary'!F11,'Table 3.10-NonPARS Wst Summary'!F17) -> 21974.77
B25: Processing & Transport | C25: Clerk/MH | D25: Sort/Transport | E25: ='Table 3.4-NonPARS Fwd Summary'!F17 -> 25880.033 | H25: ='Table 3.7-NonPARS RTS Summary'!F23 -> 75840.918 | K25: 0
B26: Accountable Unit | C26: Carrier/Clerk | D26: Postage Due | E26: =SUM('Table 3.4-NonPARS Fwd Summary'!F18:F21) -> 9457.8469 | H26: =SUM('Table 3.7-NonPARS RTS Summary'!F24:F26) -> 31437.565 | K26: 0
D27: Subtotal | E27: =SUM(E22:E26) -> 53929.515 | F27: ='Table 3.4-NonPARS Fwd Summary'!B24 -> 50713.501 | G27: =E27/F27 -> 1.0634153 | H27: =SUM(H22:H26) -> 161384.08 | I27: ='Table 3.7-NonPARS RTS Summary'!B29 -> 106886.53 | J27: =H27/I27 -> 1.5098636 | K27: =SUM(K22:K26) -> 120360.29 | L27: ='Table 3.10-NonPARS Wst Summary'!B20 -> 1452394.8 | M27: =K27/L27 -> 0.082870226
B29: Activities Directly Associated with UAA Mail -- All Pieces
E30: Final Disposition
E31: Forwarded | H31: Returned To Sender | K31: Wasted
E32: Cost | F32: Volume | G32: Unit | H32: Cost | I32: Volume | J32: Unit | K32: Cost | L32: Volume | M32: Unit
B33: Module | C33: Craft | D33: Activity | E33: ($000) | F33: (000) | G33: Cost | H33: ($000) | I33: (000) | J33: Cost | K33: ($000) | L33: (000) | M33: Cost
B34: Route | C34: Carrier/Clerk | D34: Identify/Separate | E34: =E8+E22 -> 14399.983 | H34: =H8+H22 -> 123710.93 | K34: =K8+K22 -> 119946.43
B35: Nixie Unit | C35: Clerk | D35: Nixie Work (4) | E35: =E9+E23 -> 5087.6983 | H35: =H9+H23 -> 27168.226 | K35: =K9+K23 -> 32634.484
B36: CFS Unit | C36: Clerk | D36: Key/Label, Etc. (5) | E36: =E10+E24 -> 8458.9861 | H36: =H10+H24 -> 23268.079 | K36: =K10+K24 -> 22757.689
B37: CIOSS | C37: Clerk/MH | D37: Image Lift/Label | E37: =E11 -> 18364.914 | H37: =H11 -> 30449.431 | K37: =K11 -> 30061.77
B38: REC Site | C38: Clerk | D38: Keying (5) | E38: =E12 -> 3047.9562 | H38: =H12 -> 15541.654 | K38: =K12 -> 6238.3219
B39: Processing & Transport | C39: Clerk/MH | D39: Sort/Transport | E39: =E13+E25 -> 84505.852 | H39: =H13+H25 -> 250097.01 | K39: =K13+K25 -> 0
B40: Accountable Unit | C40: Carrier/Clerk | D40: Postage Due | E40: =E14+E26 -> 9457.8469 | H40: =H14+H26 -> 35699.733 | K40: =K14+K26 -> 0
D41: Subtotal | E41: =SUM(E34:E40) -> 143323.24 | F41: =F15+F27 -> 429021.79 | G41: =E41/F41 -> 0.33406983 | H41: =SUM(H34:H40) -> 505935.06 | I41: =I15+I27 -> 1231348.8 | J41: =H41/I41 -> 0.41087875 | K41: =SUM(K34:K40) -> 211638.7 | L41: =L15+L27 -> 2299076.1 | M41: =K41/L41 -> 0.092053803
B44: Address Correction | E44: PARS | H44: Non-PARS | K44: Total
...

Sheet Table 3.2-Total Fwd Summary
A1: Table 3.2 - Cost of Forwarded UAA Mail, All Pieces
A2: PARS Environment, FY 25
B3: Volume (000s) | D3: Cost/Piece | F3: Total Cost (000s) | H3: Frequency | J3: Cost Contribution
A5: PARS Pieces (1)
A6: Plant-Intercepted COA Mail Forwarded | B6: ='Table 3.3-PARS Fwd Summary'!B10 -> 317286.89 | D6: =F6/B6 -> 0.060304278 | F6: ='Table 3.3-PARS Fwd Summary'!F10 -> 19133.757 | H6: =B6/$B$34 -> 0.73955891 | J6: =D6*H6 -> 0.044598566
A7: Carrier-Identified COA Mail Forwarded | B7: ='Table 3.3-PARS Fwd Summary'!B20 -> 61021.399 | D7: =F7/B7 -> 0.19065683 | F7: ='Table 3.3-PARS Fwd Summary'!F20 -> 11634.146 | H7: =B7/$B$34 -> 0.1422338 | J7: =D7*H7 -> 0.027117845
A8: Total | B8: =SUM(B6:B7) -> 378308.29 | D8: =F8/B8 -> 0.081330238 | F8: =SUM(F6:F7) -> 30767.903 | H8: =B8/$B$34 -> 0.88179272 | J8: =SUM(J6:J7) -> 0.071716411
A10: Downstream Activities
A11: Mailstream Processing & Transportation | B11: ='Table 3.3-PARS Fwd Summary'!B23 -> 378308.29 | D11: =F11/B11 -> 0.15496837 | F11: ='Table 3.3-PARS Fwd Summary'!F23 -> 58625.819 | H11: =B11/$B$34 -> 0.88179272 | J11: =D11*H11 -> 0.13664998
A12: Destinating Accountable Mail Unit | B12: ='Table 3.3-PARS Fwd Summary'!B24 -> 0 | D12: 0 | F12: ='Table 3.3-PARS Fwd Summary'!F24 -> 0 | H12: =B12/$B$34 -> 0 | J12: =D12*H12 -> 0
A13: Collection Postage Due - Carrier | B13: ='Table 3.3-PARS Fwd Summary'!B25 -> 0 | D13: 0 | F13: ='Table 3.3-PARS Fwd Summary'!F25 -> 0 | H13: =B13/$B$34 -> 0 | J13: =D13*H13 -> 0
A14: Collection Postage Due - Wind. Serv. | B14: ='Table 3.3-PARS Fwd Summary'!B26 -> 0 | D14: 0 | F14: ='Table 3.3-PARS Fwd Summary'!F26 -> 0 | H14: =B14/$B$34 -> 0 | J14: =D14*H14 -> 0
A15: Total | B15: =B11 -> 378308.29 | D15: =F15/B15 -> 0.15496837 | F15: =SUM(F11:F14) -> 58625.819 | H15: =B15/$B$34 -> 0.88179272 | J15: =SUM(J11:J14) -> 0.13664998
A17: Total PARS Pieces | B17: =B8 -> 378308.29 | D17: =F17/B17 -> 0.23629861 | F17: =SUM(F8,F15) -> 89393.722 | H17: =B17/$B$34 -> 0.88179272 | J17: =J8+J15 -> 0.20836639
A19: Non-PARS Pieces (2)
A20: Delivery Unit Hand Forwarded | B20: ='Table 3.4-NonPARS Fwd Summary'!B8 -> 32140.753 | D20: =F20/B20 -> 0.29284283 | F20: ='Table 3.4-NonPARS Fwd Summary'!F8 -> 9412.1889 | H20: =B20/$B$34 -> 0.074916364 | J20: =D20*H20 -> 0.02193872
A21: CFS Unit COA Mail Forwarded | B21: ='Table 3.4-NonPARS Fwd Summary'!B14 -> 18572.748 | D21: =F21/B21 -> 0.49424273 | F21: ='Table 3.4-NonPARS Fwd Summary'!F14 -> 9179.4458 | H21: =B21/$B$34 -> 0.04329092 | J21: =D21*H21 -> 0.021396223
A22: Total | B22: =SUM(B20:B21) -> 50713.501 | D22: =F22/B22 -> 0.36660129 | F22: =SUM(F20:F21) -> 18591.635 | H22: =B22/$B$34 -> 0.11820728 | J22: =SUM(J20:J21) -> 0.043334943
A24: Downstream Activities
A25: Mailstream Processing & Transportation | B25: ='Table 3.4-NonPARS Fwd Summary'!B17 -> 50713.501 | D25: =F25/B25 -> 0.51031841 | F25: ='Table 3.4-NonPARS Fwd Summary'!F17 -> 25880.033 | H25: =B25/$B$34 -> 0.11820728 | J25: =D25*H25 -> 0.060323354
A26: Destinating Accountable Mail Unit | B26: ='Table 3.4-NonPARS Fwd Summary'!B18 -> 1376.7222 | D26: =F26/B26 -> 3.0195033 | F26: ='Table 3.4-NonPARS Fwd Summary'!F18 -> 4157.0172 | H26: =B26/$B$34 -> 0.0032089796 | J26: =D26*H26 -> 0.0096895246
A27: Collection Postage Due - Carrier | B27: ='Table 3.4-NonPARS Fwd Summary'!B19 -> 1002.8017 | D27: =F27/B27 -> 0.9129758 | F27: ='Table 3.4-NonPARS Fwd Summary'!F19 -> 915.53372 | H27: =B27/$B$34 -> 0.0023374145 | J27: =D27*H27 -> 0.0021340029
A28: Collection Postage Due - Wind. Serv. | B28: ='Table 3.4-NonPARS Fwd Summary'!B20 -> 373.92043 | D28: =F28/B28 -> 0.5277623 | F28: ='Table 3.4-NonPARS Fwd Summary'!F20 -> 197.34111 | H28: =B28/$B$34 -> 0.00087156513 | J28: =D28*H28 -> 0.00045997922
A29: Prepare and Mail Form 3546 | B29: ='Table 3.4-NonPARS Fwd Summary'!B21 -> 794.94389 | D29: =F29/B29 -> 5.2682396 | F29: ='Table 3.4-NonPARS Fwd Summary'!F21 -> 4187.9549 | H29: =B29/$B$34 -> 0.001852922 | J29: =D29*H29 -> 0.0097616369
A30: Total | B30: =B25 -> 50713.501 | D30: =F30/B30 -> 0.69681406 | F30: =SUM(F25:F29) -> 35337.88 | H30: =B30/$B$34 -> 0.11820728 | J30: =SUM(J25:J29) -> 0.082368498
A32: Total Non-PARS Pieces | B32: =B22 -> 50713.501 | D32: =F32/B32 -> 1.0634153 | F32: =SUM(F22,F30) -> 53929.515 | H32: =B32/$B$34 -> 0.11820728 | J32: =J22+J30 -> 0.12570344
A34: Grand Total | B34: =SUM(B17,B32) -> 429021.79 | F34: =SUM(F17,F32) -> 143323.24 | J34: =SUM(J17,J32) -> 0.33406983
A37: checks ---> | B37: 0 | G37: route module ---> | H37: =SUM('Table 3.14-Route UAA'!J102,'Table 3.14-Route UAA'!J106) -> 14399.983 | J37: ='Table 3.3-PARS Fwd Summary'!J32+'Table 3.4-NonPARS Fwd Summary'!J27 -> 14399.983 | K37: =H37-J37 -> 0
B38: 0 | G38: nixie module ---> | H38: =SUM('Table 3.18-Nixie UAA'!I6,'Table 3.18-Nixie UAA'!I15,'Table 3.18-Nixie UAA'!I24)+SUM('Table 3.31-Rating Post Due'!H7,'Table 3.31-Rating Post Due'!H12,'Table 3.31-Rating Post Due'!H20) -> 5087.6983 | J38: ='Table 3.3-PARS Fwd Summary'!J33+'Table 3.4-NonPARS Fwd Summary'!J28 -> 5087.6983 | K38: =H38-J38 -> 0
B39: 0 | G39: cfs module ---> | H39: =SUM('Table 3.20-CFS Non-CIOSS'!H9,'Table 3.20-CFS Non-CIOSS'!H45,'Table 3.20-CFS Non-CIOSS'!H56,'Table 3.21-CFS CIOSS Rejs'!H9) -> 8458.9861 | J39: ='Table 3.3-PARS Fwd Summary'!J34+'Table 3.4-NonPARS Fwd Summary'!J29 -> 8458.9861 | K39: =H39-J39 -> 0
G40: cioss module ---> | H40: =SUM('Table 3.23-CIOSS Summary'!I4,'Table 3.23-CIOSS Summary'!I8,'Table 3.23-CIOSS Summary'!I11) -> 18364.914 | J40: ='Table 3.3-PARS Fwd Summary'!J35 -> 18364.914 | K40: =H40-J40 -> 0
G41: rec module ---> | H41: ='Table 3.25-REC Summary'!K4+'Table 3.25-REC Summary'!K8 -> 3047.9562 | J41: ='Table 3.3-PARS Fwd Summary'!J36 -> 3047.9562 | K41: =H41-J41 -> 0
G42: mp trans module ---> | H42: ='Table 3.3-PARS Fwd Summary'!H37+'Table 3.4-NonPARS Fwd Summary'!H30 -> 84505.852 | J42: ='Table 3.3-PARS Fwd Summary'!J37+'Table 3.4-NonPARS Fwd Summary'!J30 -> 84505.852 | K42: =H42-J42 -> 0
G43: pd module ---> | H43: =SUM('Table 3.32-Accounting Post Due'!D4:D5)*'Table 3.32-Accounting Post Due'!F4+SUM('Table 3.33-Delivery Post Due'!D5:D9)*'Table 3.33-Delivery Post Due'!F5+SUM('Table 3.34-Window Post Due'!D4:D5)*'Table 3.34-Window Post Due'!F4+'Table 3.36-Process Form 3546'!J17*'Table 3.36-Process Form 3546'!B4 -> 9457.8469 | J43: ='Table 3.3-PARS Fwd Summary'!J38+'Table 3.4-NonPARS Fwd Summary'!J31 -> 9457.8469 | K43: =H43-J43 -> 0
G44: Total ---> | H44: =SUM(H37:H43) -> 143323.24 | J44: =SUM(J37:J43) -> 143323.24 | K44: =H44-J44 -> 0
A46: Notes:
A47: (1) Refer to Table 3.3.
A48: (2) Refer to Table 3.4.

Sheet Table 3.3-PARS Fwd Summary
A1: Table 3.3 - Cost of Forwarded UAA Mail, PARS Pieces
A2: PARS Environment, FY 25
B3: Volume (000s) | D3: Cost/Piece | F3: Total Cost (000s) | H3: Frequency | J3: Cost Contribution
A4: Plant-Intercepted COA Mail Forwarded (1)
A5: CIOSS Processing | B5: =SUM('Table 3.24-CIOSS Detail'!E4,'Table 3.24-CIOSS Detail'!E8) -> 317286.89 | C5: (4) | D5: =F5/B5 -> 0.048544837 | F5: =SUM('Table 3.24-CIOSS Detail'!K4,'Table 3.24-CIOSS Detail'!K8) -> 15402.64 | G5: (4) | H5: =B5/$B$29 -> 0.83869928 | J5: =D5*H5 -> 0.04071452
A6: AFR Finalization | B6: =SUM('Table 3.28-REC Volume'!G4,'Table 3.28-REC Volume'!G8) -> 289644.86 | C6: (5) | D6: =F6/B6 -> 0 | F6: 0 | H6: =B6/$B$29 -> 0.76563181 | J6: =D6*H6 -> 0
A7: REC Site Finalization, Non-ACS Pieces | B7: =SUM('Table 3.28-REC Volume'!H4) -> 17651.077 | C7: (5) | D7: =F7/B7 -> 0.10707332 | F7: ='Table 3.26-REC Detail NonACS'!K4 -> 1889.9594 | G7: (6) | H7: =B7/$B$29 -> 0.046657918 | J7: =D7*H7 -> 0.0049958182
A8: REC Site Finalization, ACS Pieces (17) | B8: =SUM('Table 3.28-REC Volume'!H8) -> 5231.6497 | C8: (5) | D8: =F8/B8 -> 0.053536661 | F8: ='Table 3.26-REC Detail NonACS'!K8 -> 280.08505 | G8: (6) | H8: =B8/$B$29 -> 0.013829064 | J8: =D8*H8 -> 0.00074036193
A9: CIOSS Rejects - CFS Unit Processing | B9: 4759.3033 | C9: (7) | D9: ='Table 3.21-CFS CIOSS Rejs'!I9 -> 0.32800427 | E9: (8) | F9: =B9*D9 -> 1561.0718 | H9: =B9/$B$29 -> 0.012580489 | J9: =D9*H9 -> 0.0041264542
A10: Total | B10: =B5 -> 317286.89 | D10: =F10/B10 -> 0.060304278 | F10: =SUM(F5:F9) -> 19133.757 | J10: =SUM(J5:J9) -> 0.050577154
A12: Carrier-Identified COA Mail Forwarded (2)
A13: Carrier Preparation | B13: ='Table 3.16-Route UAA PARS'!D106 -> 61021.399 | C13: (9) | D13: =F13/B13 -> 0.1152115 | F13: ='Table 3.16-Route UAA PARS'!J106 -> 7030.3672 | G13: (9) | H13: =B13/$B$29 -> 0.16130072 | J13: =D13*H13 -> 0.018583699
A14: Clerk Handling - Prep for CIOSS | B14: ='Table 3.18-Nixie UAA'!D6 -> 61021.399 | C14: (10) | D14: =F14/B14 -> 0.0075934757 | F14: ='Table 3.18-Nixie UAA'!I6 -> 463.36451 | G14: (10) | H14: =B14/$B$29 -> 0.16130072 | J14: =D14*H14 -> 0.0012248331
A15: CIOSS Processing | B15: =SUM('Table 3.24-CIOSS Detail'!E19,'Table 3.24-CIOSS Detail'!E23) -> 61021.399 | C15: (4) | D15: =F15/B15 -> 0.048544837 | F15: =SUM('Table 3.24-CIOSS Detail'!K19,'Table 3.24-CIOSS Detail'!K23) -> 2962.2739 | G15: (4) | H15: =B15/$B$29 -> 0.16130072 | J15: =D15*H15 -> 0.0078303172
A16: AFR Finalization | B16: =SUM('Table 3.28-REC Volume'!G19,'Table 3.28-REC Volume'!G23) -> 50848.658 | C16: (5) | D16: =F16/B16 -> 0 | F16: 0 | H16: =B16/$B$29 -> 0.13441064 | J16: =D16*H16 -> 0
A17: REC Site Finalization, Non-ACS Pieces | B17: =SUM('Table 3.28-REC Volume'!H19) -> 7140.9077 | C17: (5) | D17: =F17/B17 -> 0.10707332 | F17: ='Table 3.26-REC Detail NonACS'!K19 -> 764.60071 | G17: (6) | H17: =B17/$B$29 -> 0.018875896 | J17: =D17*H17 -> 0.0020211048
A18: REC Site Finalization, ACS Pieces (17) | B18: =SUM('Table 3.28-REC Volume'!H23) -> 2116.5126 | C18: (5) | D18: =F18/B18 -> 0.053536661 | F18: ='Table 3.26-REC Detail NonACS'!K23 -> 113.31102 | G18: (6) | H18: =B18/$B$29 -> 0.0055946769 | J18: =D18*H18 -> 0.00029952032
A19: CIOSS Rejects - CFS Unit Processing | B19: ='Table 3.21-CFS CIOSS Rejs'!B9-B9 -> 915.32099 | C19: (11) | D19: ='Table 3.21-CFS CIOSS Rejs'!I9 -> 0.32800427 | E19: (8) | F19: =B19*D19 -> 300.22919 | H19: =B19/$B$29 -> 0.0024195108 | J19: =D19*H19 -> 0.00079360987
A20: Total | B20: =B13 -> 61021.399 | D20: =F20/B20 -> 0.19065683 | F20: =SUM(F13:F19) -> 11634.146 | J20: =SUM(J13:J19) -> 0.030753084
A22: Downstream Activities (3)
A23: Mailstream Processing & Transportation | B23: =SUM(B10,B20) -> 378308.29 | D23: ='Table 3.30-UAA MP Cost'!D8 -> 0.15496837 | E23: (13) | F23: =B23*D23 -> 58625.819 | H23: =B23/$B$29 -> 1 | J23: =D23*H23 -> 0.15496837
A24: Destinating Accountable Mail Unit | B24: ='Table 3.35-PD Vols'!B6 -> 0 | C24: (12) | D24: ='Table 3.32-Accounting Post Due'!I7 -> 3.0195033 | E24: (14) | F24: =B24*D24 -> 0 | H24: =B24/$B$29 -> 0 | J24: =D24*H24 -> 0
A25: Collection Postage Due - Carrier | B25: ='Table 3.35-PD Vols'!B7 -> 0 | C25: (12) | D25: ='Table 3.33-Delivery Post Due'!I11 -> 0.9129758 | E25: (15) | F25: =B25*D25 -> 0 | H25: =B25/$B$29 -> 0 | J25: =D25*H25 -> 0
A26: Collection Postage Due - Wind. Serv. | B26: ='Table 3.35-PD Vols'!B8 -> 0 | C26: (12) | D26: ='Table 3.34-Window Post Due'!I7 -> 0.5277623 | E26: (16) | F26: =B26*D26 -> 0 | H26: =B26/$B$29 -> 0 | J26: =D26*H26 -> 0
A27: Total | B27: =B23 -> 378308.29 | D27: =F27/B27 -> 0.15496837 | F27: =SUM(F23:F26) -> 58625.819 | J27: =SUM(J23:J26) -> 0.15496837
A29: Total PARS Pieces | B29: =SUM(B10,B20) -> 378308.29 | F29: =SUM(F10,F20,F27) -> 89393.722 | J29: =SUM(J10,J20,J27) -> 0.23629861
A32: checks ---> | B32: =B5-SUM(B6:B9) -> 0 | G32: route module ---> | H32: =SUM('Table 3.16-Route UAA PARS'!J106) -> 7030.3672 | J32: =SUM(F13) -> 7030.3672 | K32: =H32-J32 -> 0
B33: =B15-SUM(B16:B19) -> 0 | G33: nixie module ---> | H33: =SUM('Table 3.18-Nixie UAA'!I6) -> 463.36451 | J33: =SUM(F14) -> 463.36451 | K33: =H33-J33 -> 0
B34: =B29-SUM('Table 3.23-CIOSS Summary'!C4,'Table 3.23-CIOSS Summary'!C8,'Table 3.23-CIOSS Summary'!C11) -> 0 | G34: cfs module ---> | H34: =SUM('Table 3.21-CFS CIOSS Rejs'!H9) -> 1861.301 | J34: =SUM(F9,F19) -> 1861.301 | K34: =H34-J34 -> 0
G35: cioss module ---> | H35: =SUM('Table 3.23-CIOSS Summary'!I4,'Table 3.23-CIOSS Summary'!I8,'Table 3.23-CIOSS Summary'!I11) -> 18364.914 | J35: =SUM(F5,F15) -> 18364.914 | K35: =H35-J35 -> 0
G36: rec module ---> | H36: ='Table 3.25-REC Summary'!K4+'Table 3.25-REC Summary'!K8 -> 3047.9562 | J36: =SUM(F7:F8,F17:F18) -> 3047.9562 | K36: =H36-J36 -> 0
G37: mp trans module ---> | H37: ='Table 3.30-UAA MP Cost'!F8 -> 58625.819 | J37: =F23 -> 58625.819 | K37: =H37-J37 -> 0
G38: pd module ---> | H38: =SUM(F24:F26) -> 0 | J38: =SUM(F24:F26) -> 0 | K38: =H38-J38 -> 0
G39: Total ---> | H39: =SUM(H32:H38) -> 89393.722 | J39: =SUM(J32:J38) -> 89393.722 | K39: =H39-J39 -> 0
A41: Notes:
A42: (1) COA mail that is intercepted at the plant and forwarded. | E42: (12) Refer to Table 3.35.
A43: (2) COA mail that is identified by carriers at the original delivery unit as being forwarded. | E43: (13) Refer to Table 3.30.
A44: (3) Activities that occur after mail has been redirected. | E44: (14) Refer to Table 3.32.
A45: (4) Refer to Table 3.24. | E45: (15) Refer to Table 3.33.
A46: (5) Refer to Table 3.28. | E46: (16) Refer to Table 3.34.
...

Sheet Table 3.4-NonPARS Fwd Summary
A1: Table 3.4 - Cost of Forwarded UAA Mail, Non-PARS Pieces
A2: PARS Environment, FY 25
B3: Volume (000s) | D3: Cost/Piece | F3: Total Cost (000s) | H3: Frequency | J3: Cost Contribution
A4: Delivery Unit Hand Forwarded (1)
A5: Carrier Preparation | B5: ='Table 3.15-Route UAA NoPARS'!D102 -> 32140.753 | C5: (4) | D5: =F5/B5 -> 0.14896525 | F5: ='Table 3.15-Route UAA NoPARS'!J102 -> 4787.8552 | G5: (4) | H5: =B5/$B$24 -> 0.63377113 | J5: =D5*H5 -> 0.094409873
A6: Clerk Handling - Prep/Mark Up | B6: =SUM('Table 3.18-Nixie UAA'!D15,'Table 3.18-Nixie UAA'!D24) -> 32140.753 | C6: (5) | D6: =F6/B6 -> 0.14241007 | F6: =SUM('Table 3.18-Nixie UAA'!I15,'Table 3.18-Nixie UAA'!I24) -> 4577.167 | G6: (5) | H6: =B6/$B$24 -> 0.63377113 | J6: =D6*H6 -> 0.090255394
A7: Originating Postage Due Unit | B7: =SUM('Table 3.31-Rating Post Due'!B12,'Table 3.31-Rating Post Due'!B20) -> 211.22318 | C7: (6) | D7: =F7/B7 -> 0.22330302 | F7: =SUM('Table 3.31-Rating Post Due'!H12,'Table 3.31-Rating Post Due'!H20) -> 47.166773 | G7: (6) | H7: =B7/$B$24 -> 0.0041650285 | J7: =D7*H7 -> 0.00093006345
A8: Total | B8: =B5 -> 32140.753 | D8: =F8/B8 -> 0.29284283 | F8: =SUM(F5:F7) -> 9412.1889 | J8: =SUM(J5:J7) -> 0.18559533
A10: CFS Unit COA Mail Forwarded (2)
A11: Carrier Preparation | B11: ='Table 3.15-Route UAA NoPARS'!D106 -> 18572.748 | C11: (4) | D11: =F11/B11 -> 0.13900801 | F11: ='Table 3.15-Route UAA NoPARS'!J106 -> 2581.7607 | G11: (4) | H11: =B11/$B$24 -> 0.36622887 | J11: =D11*H11 -> 0.050908746
A12: CFS Processing | B12: ='Table 3.20-CFS Non-CIOSS'!B9 -> 18572.748 | C12: (7) | D12: =F12/B12 -> 0.32800427 | F12: ='Table 3.20-CFS Non-CIOSS'!H9 -> 6091.9407 | G12: (7) | H12: =B12/$B$24 -> 0.36622887 | J12: =D12*H12 -> 0.12012463
A13: CFS Postage Due Unit | B13: ='Table 3.20-CFS Non-CIOSS'!B45+'Table 3.20-CFS Non-CIOSS'!B56 -> 1165.499 | C13: (7) | D13: =F13/B13 -> 0.4339295 | F13: ='Table 3.20-CFS Non-CIOSS'!H45+'Table 3.20-CFS Non-CIOSS'!H56 -> 505.74439 | G13: (7) | H13: =B13/$B$24 -> 0.022982026 | J13: =D13*H13 -> 0.009972579
A14: Total | B14: =B11 -> 18572.748 | D14: =F14/B14 -> 0.49424273 | F14: =SUM(F11:F13) -> 9179.4458 | J14: =SUM(J11:J13) -> 0.18100596
A16: Downstream Activities (3)
A17: Mailstream Processing & Transportation | B17: =SUM(B8,B14) -> 50713.501 | D17: ='Table 3.30-UAA MP Cost'!D16 -> 0.51031841 | E17: (10) | F17: =B17*D17 -> 25880.033 | H17: =B17/$B$24 -> 1 | J17: =D17*H17 -> 0.51031841
A18: Destinating Accountable Mail Unit | B18: ='Table 3.35-PD Vols'!D6 -> 1376.7222 | C18: (8) | D18: ='Table 3.32-Accounting Post Due'!I7 -> 3.0195033 | E18: (11) | F18: =B18*D18 -> 4157.0172 | H18: =B18/$B$24 -> 0.027147055 | J18: =D18*H18 -> 0.081970621
A19: Collection Postage Due - Carrier | B19: ='Table 3.35-PD Vols'!D7 -> 1002.8017 | C19: (8) | D19: ='Table 3.33-Delivery Post Due'!I11 -> 0.9129758 | E19: (12) | F19: =B19*D19 -> 915.53372 | H19: =B19/$B$24 -> 0.019773861 | J19: =D19*H19 -> 0.018053057
A20: Collection Postage Due - Wind. Serv. | B20: ='Table 3.35-PD Vols'!D8 -> 373.92043 | C20: (8) | D20: ='Table 3.34-Window Post Due'!I7 -> 0.5277623 | E20: (13) | F20: =B20*D20 -> 197.34111 | H20: =B20/$B$24 -> 0.007373193 | J20: =D20*H20 -> 0.0038912933
A21: Prepare and Mail Form 3546 | B21: ='Table 3.36-Process Form 3546'!B4 -> 794.94389 | C21: (9) | D21: ='Table 3.36-Process Form 3546'!J17 -> 5.2682396 | E21: (9) | F21: =B21*D21 -> 4187.9549 | H21: =B21/$B$24 -> 0.015675193 | J21: =D21*H21 -> 0.082580671
A22: Total | B22: =B17 -> 50713.501 | D22: =F22/B22 -> 0.69681406 | F22: =SUM(F17:F21) -> 35337.88 | J22: =SUM(J17:J21) -> 0.69681406
A24: Total Non-PARS Pieces | B24: =SUM(B8,B14) -> 50713.501 | F24: =SUM(F8,F14,F22) -> 53929.515 | J24: =SUM(J8,J14,J22) -> 1.0634153
A27: checks ---> | G27: route module ---> | H27: =SUM('Table 3.15-Route UAA NoPARS'!J102,'Table 3.15-Route UAA NoPARS'!J106) -> 7369.6159 | J27: =SUM(F5,F11) -> 7369.6159 | K27: =H27-J27 -> 0
G28: nixie module ---> | H28: =SUM('Table 3.18-Nixie UAA'!I15,'Table 3.18-Nixie UAA'!I24)+SUM('Table 3.31-Rating Post Due'!H12,'Table 3.31-Rating Post Due'!H20) -> 4624.3337 | J28: =SUM(F6:F7) -> 4624.3337 | K28: =H28-J28 -> 0
G29: cfs module ---> | H29: =SUM('Table 3.20-CFS Non-CIOSS'!H9,'Table 3.20-CFS Non-CIOSS'!H45,'Table 3.20-CFS Non-CIOSS'!H56) -> 6597.6851 | J29: =SUM(F12:F13) -> 6597.6851 | K29: =H29-J29 -> 0
G30: mp trans module ---> | H30: ='Table 3.30-UAA MP Cost'!F16 -> 25880.033 | J30: =F17 -> 25880.033 | K30: =H30-J30 -> 0
G31: pd module ---> | H31: =SUM(F18:F21) -> 9457.8469 | J31: =SUM(F18:F21) -> 9457.8469 | K31: =H31-J31 -> 0
G32: Total ---> | H32: =SUM(H27:H31) -> 53929.515 | J32: =SUM(J27:J31) -> 53929.515 | K32: =H32-J32 -> 0
A34: Notes:
A35: (1) Mail being hand forwarded from the delivery unit. | C35: (8) Refer to Table 3.35.
A36: (2) Mail directly sent to CFS unit which is then forwarded. | C36: (9) Refer to Table 3.36.
A37: (3) Activities that occur after mail has been redirected. | C37: (10) Refer to Table 3.30.
A38: (4) Refer to Table 3.15. | C38: (11) Refer to Table 3.32.
A39: (5) Refer to Table 3.18. | C39: (12) Refer to Table 3.33.
A40: (6) Refer to Table 3.31. | C40: (13) Refer to Table 3.34.
A41: (7) Refer to Table 3.20.

Sheet Table 3.5-Total RTS Summary
A1: Table 3.5 - Cost of Returned-to-Sender UAA Mail, All Pieces
A2: PARS Environment, FY 25
B3: Volume (000s) | D3: Cost/Piece | F3: Total Cost (000s) | H3: Frequency | J3: Cost Contribution
A5: PARS Pieces (1)
A6: Plant-Intercepted Old COA RTS | B6: ='Table 3.6-PARS RTS Summary'!B10 -> 16936.488 | D6: =F6/B6 -> 0.058504509 | F6: ='Table 3.6-PARS RTS Summary'!F10 -> 990.86094 | H6: =B6/$B$38 -> 0.01375442 | J6: =D6*H6 -> 0.00080469557
A7: Plant-Intercepted COA Mail RTS | B7: ='Table 3.6-PARS RTS Summary'!B18 -> 169632.35 | D7: =F7/B7 -> 0.061095796 | F7: ='Table 3.6-PARS RTS Summary'!F18 -> 10363.823 | H7: =B7/$B$38 -> 0.13776141 | J7: =D7*H7 -> 0.0084166429
A8: Carrier-Identified COA Mail RTS | B8: ='Table 3.6-PARS RTS Summary'!B28 -> 32624.113 | D8: =F8/B8 -> 0.19382255 | F8: ='Table 3.6-PARS RTS Summary'!F28 -> 6323.2888 | H8: =B8/$B$38 -> 0.026494615 | J8: =D8*H8 -> 0.0051352539
A9: Carrier-Identified Nixie Mail RTS | B9: ='Table 3.6-PARS RTS Summary'!B38 -> 770334.76 | D9: =F9/B9 -> 0.16624957 | F9: ='Table 3.6-PARS RTS Summary'!F38 -> 128067.82 | H9: =B9/$B$38 -> 0.62560238 | J9: =D9*H9 -> 0.10400613
A10: Plant-Intercepted ACS Nixie Mail RTS | B10: ='Table 3.6-PARS RTS Summary'!B49 -> 3847.4579 | D10: =F10/B10 -> 0.05280218 | F10: ='Table 3.6-PARS RTS Summary'!F49 -> 203.15416 | H10: =B10/$B$38 -> 0.0031245881 | J10: =D10*H10 -> 0.00016498506
A11: Carrier-Identified ACS Nixie Mail RTS | B11: ='Table 3.6-PARS RTS Summary'!B59 -> 131087.13 | D11: =F11/B11 -> 0.15320937 | F11: ='Table 3.6-PARS RTS Summary'!F59 -> 20083.776 | H11: =B11/$B$38 -> 0.10645816 | J11: =D11*H11 -> 0.016310387
A12: Total | B12: =SUM(B6:B11) -> 1124462.3 | D12: =F12/B12 -> 0.14765522 | F12: =SUM(F6:F11) -> 166032.72 | H12: =B12/$B$38 -> 0.91319557 | J12: =SUM(J6:J11) -> 0.13483809
A14: Downstream Activities
A15: Mailstream Processing & Transportation | B15: ='Table 3.6-PARS RTS Summary'!B62 -> 1124462.3 | D15: =F15/B15 -> 0.15496837 | F15: ='Table 3.6-PARS RTS Summary'!F62 -> 174256.09 | H15: =B15/$B$38 -> 0.91319557 | J15: =D15*H15 -> 0.14151643
A16: Destinating Accountable Mail Unit | B16: ='Table 3.6-PARS RTS Summary'!B63 -> 1114.2542 | D16: =F16/B16 -> 3.0195033 | F16: ='Table 3.6-PARS RTS Summary'!F63 -> 3364.4941 | H16: =B16/$B$38 -> 0.00090490537 | J16: =D16*H16 -> 0.0027323648
A17: Collection Postage Due - Carrier | B17: ='Table 3.6-PARS RTS Summary'!B64 -> 921.92894 | D17: =F17/B17 -> 0.9129758 | F17: ='Table 3.6-PARS RTS Summary'!F64 -> 841.69881 | H17: =B17/$B$38 -> 0.00074871468 | J17: =D17*H17 -> 0.00068355839
A18: Collection Postage Due - Wind. Serv. | B18: ='Table 3.6-PARS RTS Summary'!B65 -> 106.06226 | D18: =F18/B18 -> 0.5277623 | F18: ='Table 3.6-PARS RTS Summary'!F65 -> 55.975663 | H18: =B18/$B$38 -> 8.6135025e-05 | J18: =D18*H18 -> 4.5458819e-05
A19: Total | B19: =B15 -> 1124462.3 | D19: =F19/B19 -> 0.15875878 | F19: =SUM(F15:F18) -> 178518.26 | H19: =B19/$B$38 -> 0.91319557 | J19: =SUM(J15:J18) -> 0.14497781
A21: Total PARS Pieces | B21: =B12 -> 1124462.3 | D21: =F21/B21 -> 0.30641399 | F21: =SUM(F12,F19) -> 344550.98 | H21: =B21/$B$38 -> 0.91319557 | J21: =J12+J19 -> 0.2798159
A23: Non-PARS Pieces (2)
A24: Delivery Unit RTS | B24: ='Table 3.7-NonPARS RTS Summary'!B8 -> 36777.475 | D24: =F24/B24 -> 0.63877381 | F24: ='Table 3.7-NonPARS RTS Summary'!F8 -> 23492.488 | H24: =B24/$B$38 -> 0.029867634 | J24: =D24*H24 -> 0.019078662
A25: CFS Unit COA Mail RTS | B25: ='Table 3.7-NonPARS RTS Summary'!B14 -> 59033.92 | D25: =F25/B25 -> 0.48596785 | F25: ='Table 3.7-NonPARS RTS Summary'!F14 -> 28688.587 | H25: =B25/$B$38 -> 0.047942483 | J25: =D25*H25 -> 0.023298506
A26: CFS Unit ACS Nixie RTS | B26: ='Table 3.7-NonPARS RTS Summary'!B20 -> 11075.134 | D26: =F26/B26 -> 0.17376955 | F26: ='Table 3.7-NonPARS RTS Summary'!F20 -> 1924.5212 | H26: =B26/$B$38 -> 0.0089943112 | J26: =D26*H26 -> 0.0015629374
A27: Total | B27: =SUM(B24:B26) -> 106886.53 | D27: =F27/B27 -> 0.50619659 | F27: =SUM(F24:F26) -> 54105.597 | H27: =B27/$B$38 -> 0.086804428 | J27: =SUM(J24:J26) -> 0.043940105
A29: Downstream Activities
A30: Mailstream Processing & Transportation | B30: ='Table 3.7-NonPARS RTS Summary'!B23 -> 106886.53 | D30: =F30/B30 -> 0.70954608 | F30: ='Table 3.7-NonPARS RTS Summary'!F23 -> 75840.918 | H30: =B30/$B$38 -> 0.086804428 | J30: =D30*H30 -> 0.061591742
A31: Destinating Accountable Mail Unit | B31: ='Table 3.7-NonPARS RTS Summary'!B24 -> 8586.9577 | D31: =F31/B31 -> 3.0195033 | F31: ='Table 3.7-NonPARS RTS Summary'!F24 -> 25928.347 | H31: =B31/$B$38 -> 0.0069736191 | J31: =D31*H31 -> 0.021056866
A32: Collection Postage Due - Carrier | B32: ='Table 3.7-NonPARS RTS Summary'!B25 -> 5482.023 | D32: =F32/B32 -> 0.9129758 | F32: ='Table 3.7-NonPARS RTS Summary'!F25 -> 5004.9543 | H32: =B32/$B$38 -> 0.0044520471 | J32: =D32*H32 -> 0.0040646113
A33: Collection Postage Due - Wind. Serv. | B33: ='Table 3.7-NonPARS RTS Summary'!B26 -> 955.474 | D33: =F33/B33 -> 0.5277623 | F33: ='Table 3.7-NonPARS RTS Summary'!F26 -> 504.26315 | H33: =B33/$B$38 -> 0.00077595721 | J33: =D33*H33 -> 0.00040952096
A34: Total | B34: =B30 -> 106886.53 | D34: =F34/B34 -> 1.003667 | F34: =SUM(F30:F33) -> 107278.48 | H34: =B34/$B$38 -> 0.086804428 | J34: =SUM(J30:J33) -> 0.08712274
A36: Total Non-PARS Pieces | B36: =B27 -> 106886.53 | D36: =F36/B36 -> 1.5098636 | F36: =SUM(F27,F34) -> 161384.08 | H36: =B36/$B$38 -> 0.086804428 | J36: =J27+J34 -> 0.13106285
A38: Grand Total | B38: =SUM(B21,B36) -> 1231348.8 | F38: =SUM(F21,F36) -> 505935.06 | J38: =SUM(J21,J36) -> 0.41087875
A41: checks ---> | B41: 0 | G41: route module ---> | H41: =SUM('Table 3.14-Route UAA'!J99:J100,'Table 3.14-Route UAA'!J107) -> 123710.93 | J41: ='Table 3.6-PARS RTS Summary'!J71+'Table 3.7-NonPARS RTS Summary'!J32 -> 123710.93 | K41: =H41-J41 -> 0
B42: 0 | G42: nixie module ---> | H42: =SUM('Table 3.18-Nixie UAA'!I7,'Table 3.18-Nixie UAA'!I9:I10,'Table 3.18-Nixie UAA'!I16,'Table 3.18-Nixie UAA'!I19,'Table 3.18-Nixie UAA'!I25:I25,'Table 3.18-Nixie UAA'!I28,'Table 3.18-Nixie UAA'!I33:I34,'Table 3.18-Nixie UAA'!I36)+SUM('Table 3.31-Rating Post Due'!H8,'Table 3.31-Rating Post Due'!H13,'Table 3.31-Rating Post Due'!H25) -> 27168.226 | J42: ='Table 3.6-PARS RTS Summary'!J72+'Table 3.7-NonPARS RTS Summary'!J33 -> 27168.226 | K42: =H42-J42 -> 0
B43: 0 | G43: cfs module ---> | H43: =SUM('Table 3.20-CFS Non-CIOSS'!H14,'Table 3.20-CFS Non-CIOSS'!H50,'Table 3.20-CFS Non-CIOSS'!H71,'Table 3.21-CFS CIOSS Rejs'!H14,'Table 3.21-CFS CIOSS Rejs'!H71) -> 23268.079 | J43: ='Table 3.6-PARS RTS Summary'!J73+'Table 3.7-NonPARS RTS Summary'!J34 -> 23268.079 | K43: =H43-J43 -> 0
G44: cioss module ---> | H44: =SUM('Table 3.23-CIOSS Summary'!I5,'Table 3.23-CIOSS Summary'!I9,'Table 3.23-CIOSS Summary'!I12) -> 30449.431 | J44: ='Table 3.6-PARS RTS Summary'!J74 -> 30449.431 | K44: =H44-J44 -> 0
G45: rec module ---> | H45: =SUM('Table 3.25-REC Summary'!K5,'Table 3.25-REC Summary'!K9,'Table 3.25-REC Summary'!K12) -> 15541.654 | J45: ='Table 3.6-PARS RTS Summary'!J75 -> 15541.654 | K45: =H45-J45 -> 0
G46: mp trans module ---> | H46: ='Table 3.6-PARS RTS Summary'!H76+'Table 3.7-NonPARS RTS Summary'!H35 -> 250097.01 | J46: ='Table 3.6-PARS RTS Summary'!J76+'Table 3.7-NonPARS RTS Summary'!J35 -> 250097.01 | K46: =H46-J46 -> 0
G47: pd module ---> | H47: =SUM('Table 3.32-Accounting Post Due'!D10:D11)*'Table 3.32-Accounting Post Due'!F10+SUM('Table 3.33-Delivery Post Due'!D14:D18)*'Table 3.33-Delivery Post Due'!F14+SUM('Table 3.34-Window Post Due'!D10:D11)*'Table 3.34-Window Post Due'!F10 -> 35699.733 | J47: ='Table 3.6-PARS RTS Summary'!J77+'Table 3.7-NonPARS RTS Summary'!J36 -> 35699.733 | K47: =H47-J47 -> 0
G48: Total ---> | H48: =SUM(H41:H47) -> 505935.06 | J48: =SUM(J41:J47) -> 505935.06 | K48: =H48-J48 -> 0
A51: Notes:
...

Sheet Table 3.6-PARS RTS Summary
A1: Table 3.6 - Cost of Returned-to-Sender UAA Mail, PARS Pieces -- Part 1
A2: PARS Environment, FY 25
B3: Volume (000s) | D3: Cost/Piece | F3: Total Cost (000s) | H3: Frequency | J3: Cost Contribution
A4: Plant-Intercepted Old COA RTS (1)
A5: CIOSS Processing | B5: ='Table 3.24-CIOSS Detail'!E12 -> 16936.488 | C5: (8) | D5: =F5/B5 -> 0.048544837 | F5: ='Table 3.24-CIOSS Detail'!K12 -> 822.17907 | G5: (8) | H5: =B5/$B$68 -> 0.015061855 | J5: =D5*H5 -> 0.00073117531
A6: AFR Finalization | B6: ='Table 3.28-REC Volume'!G12 -> 15460.982 | C6: (9) | D6: =F6/B6 -> 0 | F6: 0 | H6: =B6/$B$68 -> 0.013749667 | J6: =D6*H6 -> 0
A7: REC Site Finalization, Non-ACS Pieces | B7: ='Table 3.28-REC Volume'!H12 -> 1221.4593 | C7: (9) | D7: =F7/B7 -> 0.10707332 | F7: ='Table 3.26-REC Detail NonACS'!K12 -> 130.78571 | G7: (12) | H7: =B7/$B$68 -> 0.0010862608 | J7: =D7*H7 -> 0.00011630956
A8: REC Site Finalization, ACS Pieces (25) | B8: 0 | D8: 0 | F8: 0 | H8: =B8/$B$68 -> 0 | J8: =D8*H8 -> 0
A9: CIOSS Rejects - Nixie Unit Processing | B9: 254.04733 | C9: (10) | D9: ='Table 3.18-Nixie UAA'!J33 -> 0.14916969 | E9: (11) | F9: =B9*D9 -> 37.89616 | H9: =B9/$B$68 -> 0.00022592783 | J9: =D9*H9 -> 3.3701584e-05
A10: Total | B10: =B5 -> 16936.488 | D10: =F10/B10 -> 0.058504509 | F10: =SUM(F5:F9) -> 990.86094 | J10: =SUM(J5:J9) -> 0.00088118645
A12: Plant-Intercepted COA Mail RTS (2)
A13: CIOSS Processing | B13: =SUM('Table 3.24-CIOSS Detail'!E5,'Table 3.24-CIOSS Detail'!E9) -> 169632.35 | C13: (8) | D13: =F13/B13 -> 0.048544837 | F13: =SUM('Table 3.24-CIOSS Detail'!K5,'Table 3.24-CIOSS Detail'!K9) -> 8234.7747 | G13: (8) | H13: =B13/$B$68 -> 0.15085641 | J13: =D13*H13 -> 0.0073233
A14: AFR Finalization | B14: =SUM('Table 3.28-REC Volume'!G5,'Table 3.28-REC Volume'!G9) -> 154853.98 | C14: (9) | D14: =F14/B14 -> 0 | F14: 0 | H14: =B14/$B$68 -> 0.1377138 | J14: =D14*H14 -> 0
A15: REC Site Finalization, Non-ACS Pieces | B15: =SUM('Table 3.28-REC Volume'!H5) -> 11944.813 | C15: (9) | D15: =F15/B15 -> 0.10707332 | F15: =SUM('Table 3.26-REC Detail NonACS'!K5) -> 1278.9708 | G15: (12) | H15: =B15/$B$68 -> 0.010622689 | J15: =D15*H15 -> 0.0011374066
A16: REC Site Finalization, ACS Pieces (25) | B16: =SUM('Table 3.28-REC Volume'!H9) -> 289.06988 | C16: (9) | D16: =F16/B16 -> 0.053536661 | F16: =SUM('Table 3.26-REC Detail NonACS'!K9) -> 15.475836 | G16: (12) | H16: =B16/$B$68 -> 0.00025707388 | J16: =D16*H16 -> 1.3762877e-05
A17: CIOSS Rejects - CFS Unit Processing | B17: 2544.4852 | C17: (13) | D17: ='Table 3.21-CFS CIOSS Rejs'!I13 -> 0.32800427 | E17: (14) | F17: =B17*D17 -> 834.60202 | H17: =B17/$B$68 -> 0.0022628462 | J17: =D17*H17 -> 0.00074222322
A18: Total | B18: =B13 -> 169632.35 | D18: =F18/B18 -> 0.061095796 | F18: =SUM(F13:F17) -> 10363.823 | J18: =SUM(J13:J17) -> 0.0092166927
A20: Carrier-Identified COA Mail RTS (3)
A21: Carrier Preparation | B21: ='Table 3.16-Route UAA PARS'!D107 -> 32624.113 | C21: (15) | D21: =F21/B21 -> 0.11671223 | F21: ='Table 3.16-Route UAA PARS'!J107 -> 3807.633 | G21: (15) | H21: =B21/$B$68 -> 0.029013079 | J21: =D21*H21 -> 0.0033861811
A22: Clerk Handling - Prep for CIOSS | B22: ='Table 3.18-Nixie UAA'!D7 -> 32624.113 | C22: (11) | D22: =F22/B22 -> 0.0075934757 | F22: ='Table 3.18-Nixie UAA'!I7 -> 247.73041 | G22: (11) | H22: =B22/$B$68 -> 0.029013079 | J22: =D22*H22 -> 0.00022031011
A23: CIOSS Processing | B23: =SUM('Table 3.24-CIOSS Detail'!E20,'Table 3.24-CIOSS Detail'!E24) -> 32624.113 | C23: (8) | D23: =F23/B23 -> 0.048544837 | F23: =SUM('Table 3.24-CIOSS Detail'!K20,'Table 3.24-CIOSS Detail'!K24) -> 1583.7322 | G23: (8) | H23: =B23/$B$68 -> 0.029013079 | J23: =D23*H23 -> 0.0014084352
A24: AFR Finalization | B24: =SUM('Table 3.28-REC Volume'!G20,'Table 3.28-REC Volume'!G24) -> 27185.42 | C24: (9) | D24: =F24/B24 -> 0 | F24: 0 | H24: =B24/$B$68 -> 0.024176373 | J24: =D24*H24 -> 0
A25: REC Site Finalization, Non-ACS Pieces | B25: =SUM('Table 3.28-REC Volume'!H20) -> 4832.3855 | C25: (9) | D25: =F25/B25 -> 0.10707332 | F25: =SUM('Table 3.26-REC Detail NonACS'!K20) -> 517.41956 | G25: (12) | H25: =B25/$B$68 -> 0.0042975078 | J25: =D25*H25 -> 0.00046014843
A26: REC Site Finalization, ACS Pieces (25) | B26: =SUM('Table 3.28-REC Volume'!H24) -> 116.94591 | C26: (9) | D26: =F26/B26 -> 0.053536661 | F26: =SUM('Table 3.26-REC Detail NonACS'!K24) -> 6.2608937 | G26: (12) | H26: =B26/$B$68 -> 0.00010400163 | J26: =D26*H26 -> 5.5679001e-06
A27: CIOSS Rejects - CFS Unit Processing | B27: ='Table 3.21-CFS CIOSS Rejs'!B14-B17 -> 489.36169 | C27: (16) | D27: ='Table 3.21-CFS CIOSS Rejs'!I13 -> 0.32800427 | E27: (14) | F27: =B27*D27 -> 160.51273 | H27: =B27/$B$68 -> 0.00043519618 | J27: =D27*H27 -> 0.00014274621
A28: Total | B28: =B21 -> 32624.113 | D28: =F28/B28 -> 0.19382255 | F28: =SUM(F21:F27) -> 6323.2888 | J28: =SUM(J21:J27) -> 0.0056233889
A30: Carrier-Identified Nixie Mail RTS (4)
A31: Carrier Preparation | B31: ='Table 3.16-Route UAA PARS'!D99 -> 770334.76 | C31: (15) | D31: =F31/B31 -> 0.11690357 | F31: ='Table 3.16-Route UAA PARS'!J99 -> 90054.881 | G31: (15) | H31: =B31/$B$68 -> 0.68506944 | J31: =D31*H31 -> 0.080087062
A32: Clerk Handling - Prep for CIOSS | B32: ='Table 3.18-Nixie UAA'!D9 -> 770334.76 | C32: (11) | D32: =F32/B32 -> 0.0091023433 | F32: ='Table 3.18-Nixie UAA'!I9 -> 7011.8514 | G32: (11) | H32: =B32/$B$68 -> 0.68506944 | J32: =D32*H32 -> 0.0062357373
A33: CIOSS Processing | B33: =SUM('Table 3.24-CIOSS Detail'!E27,'Table 3.24-CIOSS Detail'!E34) -> 770334.76 | C33: (8) | D33: =F33/B33 -> 0.021762259 | F33: =SUM('Table 3.24-CIOSS Detail'!K27,'Table 3.24-CIOSS Detail'!K34) -> 16764.225 | G33: (8) | H33: =B33/$B$68 -> 0.68506944 | J33: =D33*H33 -> 0.014908659
A34: AFR Finalization | B34: =SUM('Table 3.28-REC Volume'!G27,'Table 3.28-REC Volume'!G34) -> 641913.97 | C34: (9) | D34: =F34/B34 -> 0 | F34: 0 | H34: =B34/$B$68 -> 0.57086305 | J34: =D34*H34 -> 0
A35: REC Site Finalization, Non-ACS Pieces | B35: =SUM('Table 3.28-REC Volume'!H27,'Table 3.28-REC Volume'!H34) -> 116865.77 | C35: (9) | D35: =F35/B35 -> 0.10707332 | F35: =SUM('Table 3.26-REC Detail NonACS'!K27,'Table 3.26-REC Detail NonACS'!K34) -> 12513.206 | G35: (12) | H35: =B35/$B$68 -> 0.10393036 | J35: =D35*H35 -> 0.011128168
A36: REC Site Finalization, ACS Pieces (25) | B36: 0 | D36: 0 | F36: 0 | H36: =B36/$B$68 -> 0 | J36: =D36*H36 -> 0
A37: CIOSS Rejects - Nixie Unit Processing | B37: ='Table 3.18-Nixie UAA'!D33-B9 -> 11555.021 | C37: (17) | D37: ='Table 3.18-Nixie UAA'!J33 -> 0.14916969 | E37: (11) | F37: =B37*D37 -> 1723.6589 | H37: =B37/$B$68 -> 0.010276042 | J37: =D37*H37 -> 0.0015328739
A38: Total | B38: =B31 -> 770334.76 | F38: =SUM(F31:F37) -> 128067.82 | J38: =SUM(J31:J37) -> 0.1138925
A40: Table 3.6 - Cost of Returned-to-Sender UAA Mail, PARS Pieces -- Part 2
A41: PARS Environment, FY 25
B42: Volume (000s) | D42: Cost/Piece | F42: Total Cost (000s) | H42: Frequency | J42: Cost Contribution
A43: Plant-Intercepted ACS Nixie Mail RTS (5)
A44: CIOSS Processing | B44: ='Table 3.24-CIOSS Detail'!E15 -> 3847.4579 | C44: (8) | D44: =F44/B44 -> 0.048544837 | F44: ='Table 3.24-CIOSS Detail'!K15 -> 186.77422 | G44: (8) | H44: =B44/$B$68 -> 0.003421598 | J44: =D44*H44 -> 0.00016610092
...

Sheet Table 3.7-NonPARS RTS Summary
A1: Table 3.7 - Cost of Returned-to-Sender UAA Mail, Non-PARS Pieces
A2: PARS Environment, FY 25
B3: Volume (000s) | D3: Cost/Piece | F3: Total Cost (000s) | H3: Frequency | J3: Cost Contribution
A4: Delivery Unit RTS (1)
A5: Carrier Preparation | B5: ='Table 3.15-Route UAA NoPARS'!D99 -> 36777.475 | C5: (5) | D5: =F5/B5 -> 0.17241005 | F5: ='Table 3.15-Route UAA NoPARS'!J99 -> 6340.8062 | G5: (5) | H5: =B5/$B$29 -> 0.34407961 | J5: =D5*H5 -> 0.059322781
A6: Clerk Handling - Prep/Mark Up | B6: =SUM('Table 3.18-Nixie UAA'!D16,'Table 3.18-Nixie UAA'!D19,'Table 3.18-Nixie UAA'!D25,'Table 3.18-Nixie UAA'!D28) -> 36777.475 | C6: (6) | D6: =F6/B6 -> 0.44415922 | F6: =SUM('Table 3.18-Nixie UAA'!I16,'Table 3.18-Nixie UAA'!I19,'Table 3.18-Nixie UAA'!I25,'Table 3.18-Nixie UAA'!I28) -> 16335.055 | G6: (6) | H6: =B6/$B$29 -> 0.34407961 | J6: =D6*H6 -> 0.15282613
A7: Originating Postage Due Unit | B7: =SUM('Table 3.31-Rating Post Due'!B14,'Table 3.31-Rating Post Due'!B25) -> 3081.2907 | C7: (7) | D7: =F7/B7 -> 0.26502763 | F7: =SUM('Table 3.31-Rating Post Due'!H14,'Table 3.31-Rating Post Due'!H25) -> 816.62719 | G7: (7) | H7: =B7/$B$29 -> 0.02882768 | J7: =D7*H7 -> 0.0076401319
A8: Total | B8: =B5 -> 36777.475 | D8: =F8/B8 -> 0.63877381 | F8: =SUM(F5:F7) -> 23492.488 | J8: =SUM(J5:J7) -> 0.21978904
A10: CFS Unit COA Mail RTS (2)
A11: Carrier Preparation | B11: ='Table 3.15-Route UAA NoPARS'!D107 -> 59033.92 | C11: (5) | D11: =F11/B11 -> 0.11453897 | F11: ='Table 3.15-Route UAA NoPARS'!J107 -> 6761.6846 | G11: (5) | H11: =B11/$B$29 -> 0.55230458 | J11: =D11*H11 -> 0.0632604
A12: CFS Processing | B12: ='Table 3.20-CFS Non-CIOSS'!B14 -> 59033.92 | C12: (8) | D12: =F12/B12 -> 0.33095941 | F12: ='Table 3.20-CFS Non-CIOSS'!H14 -> 19537.832 | G12: (8) | H12: =B12/$B$29 -> 0.55230458 | J12: =D12*H12 -> 0.1827904
A13: CFS Postage Due Unit | B13: ='Table 3.20-CFS Non-CIOSS'!B50+'Table 3.20-CFS Non-CIOSS'!B61 -> 5505.6669 | C13: (8) | D13: =F13/B13 -> 0.4339295 | F13: ='Table 3.20-CFS Non-CIOSS'!H50+'Table 3.20-CFS Non-CIOSS'!H61 -> 2389.0713 | G13: (8) | H13: =B13/$B$29 -> 0.051509455 | J13: =D13*H13 -> 0.022351472
A14: Total | B14: =B11 -> 59033.92 | D14: =F14/B14 -> 0.48596785 | F14: =SUM(F11:F13) -> 28688.587 | J14: =SUM(J11:J13) -> 0.26840227
A16: CFS Unit ACS Nixie RTS (3)
A17: Carrier Preparation | B17: ='Table 3.15-Route UAA NoPARS'!D100 -> 11075.134 | C17: (5) | D17: =F17/B17 -> 0.14735092 | F17: ='Table 3.15-Route UAA NoPARS'!J100 -> 1631.9313 | G17: (5) | H17: =B17/$B$29 -> 0.10361581 | J17: =D17*H17 -> 0.015267885
A18: Clerk Handling - Sort By Reason | B18: 0 | C18: (6) | D18: 0 | F18: 0 | G18: (6) | H18: =B18/$B$29 -> 0 | J18: =D18*H18 -> 0
A19: CFS Processing | B19: ='Table 3.20-CFS Non-CIOSS'!B71 -> 11075.134 | C19: (8) | D19: =F19/B19 -> 0.026418631 | F19: ='Table 3.20-CFS Non-CIOSS'!H71 -> 292.58988 | G19: (8) | H19: =B19/$B$29 -> 0.10361581 | J19: =D19*H19 -> 0.0027373878
A20: Total | B20: =B17 -> 11075.134 | D20: =F20/B20 -> 0.17376955 | F20: =SUM(F17:F19) -> 1924.5212 | J20: =SUM(J17:J19) -> 0.018005273
A22: Downstream Activities (4)
A23: Mailstream Processing & Transportation | B23: =SUM(B8,B14,B20) -> 106886.53 | D23: ='Table 3.30-UAA MP Cost'!D32 -> 0.70954608 | E23: (10) | F23: =B23*D23 -> 75840.918 | H23: =B23/$B$29 -> 1 | J23: =D23*H23 -> 0.70954608
A24: Destinating Accountable Mail Unit | B24: ='Table 3.35-PD Vols'!D14 -> 8586.9577 | C24: (9) | D24: ='Table 3.32-Accounting Post Due'!I13 -> 3.0195033 | E24: (11) | F24: =B24*D24 -> 25928.347 | H24: =B24/$B$29 -> 0.080337135 | J24: =D24*H24 -> 0.24257825
A25: Collection Postage Due - Carrier | B25: ='Table 3.35-PD Vols'!D15 -> 5482.023 | C25: (9) | D25: ='Table 3.33-Delivery Post Due'!I20 -> 0.9129758 | E25: (12) | F25: =B25*D25 -> 5004.9543 | H25: =B25/$B$29 -> 0.051288249 | J25: =D25*H25 -> 0.04682493
A26: Collection Postage Due - Wind. Serv. | B26: ='Table 3.35-PD Vols'!D16 -> 955.474 | C26: (9) | D26: ='Table 3.34-Window Post Due'!I13 -> 0.5277623 | E26: (13) | F26: =B26*D26 -> 504.26315 | H26: =B26/$B$29 -> 0.0089391432 | J26: =D26*H26 -> 0.0047177428
A27: Total | B27: =B23 -> 106886.53 | D27: =F27/B27 -> 1.003667 | F27: =SUM(F23:F26) -> 107278.48 | J27: =SUM(J23:J26) -> 1.003667
A29: Total Non-PARS Pieces | B29: =SUM(B8,B14,B20) -> 106886.53 | F29: =SUM(F8,F14,F20,F27) -> 161384.08 | J29: =SUM(J8,J14,J20,J27) -> 1.5098636
A32: checks ---> | G32: route module ---> | H32: =SUM('Table 3.15-Route UAA NoPARS'!J99:J100,'Table 3.15-Route UAA NoPARS'!J107) -> 14734.422 | J32: =SUM(F5,F11,F17) -> 14734.422 | K32: =H32-J32 -> 0
G33: nixie module ---> | H33: =SUM('Table 3.18-Nixie UAA'!I16:I16,'Table 3.18-Nixie UAA'!I19,'Table 3.18-Nixie UAA'!I25:I25,'Table 3.18-Nixie UAA'!I28)+SUM('Table 3.31-Rating Post Due'!H13,'Table 3.31-Rating Post Due'!H25) -> 17151.682 | J33: =SUM(F6:F7,F18) -> 17151.682 | K33: =H33-J33 -> 0
G34: cfs module ---> | H34: =SUM('Table 3.20-CFS Non-CIOSS'!H14,'Table 3.20-CFS Non-CIOSS'!H50,'Table 3.20-CFS Non-CIOSS'!H61,'Table 3.20-CFS Non-CIOSS'!H71) -> 22219.493 | J34: =SUM(F12:F13,F19) -> 22219.493 | K34: =H34-J34 -> 0
G35: mp trans module ---> | H35: ='Table 3.30-UAA MP Cost'!F32 -> 75840.918 | J35: =F23 -> 75840.918 | K35: =H35-J35 -> 0
G36: pd module ---> | H36: =SUM(F24:F26) -> 31437.565 | J36: =SUM(F24:F26) -> 31437.565 | K36: =H36-J36 -> 0
G37: Total ---> | H37: =SUM(H32:H36) -> 161384.08 | J37: =SUM(J32:J36) -> 161384.08 | K37: =H37-J37 -> 0
A39: Notes:
A40: (1) Mail being returned from the delivery unit. | E40: (8) Refer to Table 3.20.
A41: (2) Mail directly sent to CFS unit which is then returned to sender. | E41: (9) Refer to Table 3.35.
A42: (3) Address Change Service (ACS) mail sent to the nixie unit and then to the CFS unit. | E42: (10) Refer to Table 3.30.
A43: (4) Activities that occur after mail has been redirected. | E43: (11) Refer to Table 3.32.
A44: (5) Refer to Table 3.15. | E44: (12) Refer to Table 3.33.
A45: (6) Nixie clerk handling of ACS nixie mail is excluded. Refer to Table 7.18. | E45: (13) Refer to Table 3.34.
A46: (7) Refer to Table 3.31.

Sheet Table 3.8-Total Wst Summary
A1: Table 3.8 - Cost of Wasted UAA Mail, All Pieces
A2: PARS Environment, FY 25
B3: Volume (000s) | D3: Cost/Piece | F3: Total Cost (000s) | H3: Frequency | J3: Cost Contribution
A5: PARS Pieces (1)
A6: Plant-Intercepted Non-Forwardable Waste | B6: ='Table 3.9-PARS Wst Summary'!B10 -> 278110.92 | D6: =F6/B6 -> 0.056550058 | F6: ='Table 3.9-PARS Wst Summary'!F10 -> 15727.189 | H6: =B6/$B$19 -> 0.12096639 | J6: =D6*H6 -> 0.0068406561
A7: Plant-Intercepted COA Mail Waste | B7: ='Table 3.9-PARS Wst Summary'!B18 -> 103378.91 | D7: =F7/B7 -> 0.057586278 | F7: ='Table 3.9-PARS Wst Summary'!F18 -> 5953.2065 | H7: =B7/$B$19 -> 0.044965414 | J7: =D7*H7 -> 0.0025893908
A8: Carrier-Identified COA Mail Waste | B8: ='Table 3.9-PARS Wst Summary'!B28 -> 19882.087 | D8: =F8/B8 -> 0.17809757 | F8: ='Table 3.9-PARS Wst Summary'!F28 -> 3540.9513 | H8: =B8/$B$19 -> 0.0086478597 | J8: =D8*H8 -> 0.0015401628
A9: Plant-Intercepted ACS Nixie Mail Waste | B9: ='Table 3.9-PARS Wst Summary'!B36 -> 29216.412 | D9: =F9/B9 -> 0.05280218 | F9: ='Table 3.9-PARS Wst Summary'!F36 -> 1542.6902 | H9: =B9/$B$19 -> 0.012707893 | J9: =D9*H9 -> 0.00067100443
A10: Carrier-Identified ACS Nixie Mail Waste | B10: ='Table 3.9-PARS Wst Summary'!B46 -> 416092.91 | D10: =F10/B10 -> 0.15504799 | F10: ='Table 3.9-PARS Wst Summary'!F46 -> 64514.371 | H10: =B10/$B$19 -> 0.18098266 | J10: =D10*H10 -> 0.028060999
A11: Total | B11: =SUM(B6:B10) -> 846681.24 | D11: =F11/B11 -> 0.10780729 | F11: =SUM(F6:F10) -> 91278.407 | H11: =B11/$B$19 -> 0.36827021 | J11: =SUM(J6:J10) -> 0.039702213
A13: Non-PARS Pieces (2)
A14: Delivery Unit Waste | B14: ='Table 3.10-NonPARS Wst Summary'!B7 -> 1368978.5 | D14: =F14/B14 -> 0.061319533 | F14: ='Table 3.10-NonPARS Wst Summary'!F7 -> 83945.125 | H14: =B14/$B$19 -> 0.59544726 | J14: =D14*H14 -> 0.036512548
A15: CFS Unit COA Mail Waste | B15: ='Table 3.10-NonPARS Wst Summary'!B12 -> 65556.92 | D15: =F15/B15 -> 0.49680664 | F15: ='Table 3.10-NonPARS Wst Summary'!F12 -> 32569.113 | H15: =B15/$B$19 -> 0.028514463 | J15: =D15*H15 -> 0.014166175
A16: CFS Unit ACS Nixie Waste | B16: ='Table 3.10-NonPARS Wst Summary'!B18 -> 17859.366 | D16: =F16/B16 -> 0.21535199 | F16: ='Table 3.10-NonPARS Wst Summary'!F18 -> 3846.0501 | H16: =B16/$B$19 -> 0.0077680624 | J16: =D16*H16 -> 0.0016728677
A17: Total | B17: =SUM(B14:B16) -> 1452394.8 | D17: =F17/B17 -> 0.082870226 | F17: =SUM(F14:F16) -> 120360.29 | H17: =B17/$B$19 -> 0.63172979 | J17: =SUM(J14:J16) -> 0.05235159
A19: Grand Total | B19: =SUM(B11,B17) -> 2299076.1 | F19: =SUM(F11,F17) -> 211638.7 | J19: =SUM(J11,J17) -> 0.092053803
A21: checks ---> | B21: 0 | G21: route module ---> | H21: =SUM('Table 3.14-Route UAA'!J101,'Table 3.14-Route UAA'!J108,'Table 3.14-Route UAA'!J111) -> 119946.43 | J21: ='Table 3.9-PARS Wst Summary'!J50+'Table 3.10-NonPARS Wst Summary'!J22 -> 119946.43 | K21: =H21-J21 -> 0
B22: 0 | G22: nixie module ---> | H22: =SUM('Table 3.18-Nixie UAA'!I8,'Table 3.18-Nixie UAA'!I11,'Table 3.18-Nixie UAA'!I20,'Table 3.18-Nixie UAA'!I29,'Table 3.18-Nixie UAA'!I35,'Table 3.18-Nixie UAA'!I37) -> 32634.484 | J22: ='Table 3.9-PARS Wst Summary'!J51+'Table 3.10-NonPARS Wst Summary'!J23 -> 32634.484 | K22: =H22-J22 -> 0
B23: 0 | G23: cfs module ---> | H23: =SUM('Table 3.20-CFS Non-CIOSS'!H19,'Table 3.20-CFS Non-CIOSS'!H76,'Table 3.21-CFS CIOSS Rejs'!H19,'Table 3.21-CFS CIOSS Rejs'!H76) -> 22757.689 | J23: ='Table 3.9-PARS Wst Summary'!J52+'Table 3.10-NonPARS Wst Summary'!J24 -> 22757.689 | K23: =H23-J23 -> 0
G24: cioss module ---> | H24: =SUM('Table 3.23-CIOSS Summary'!I6,'Table 3.23-CIOSS Summary'!I10,'Table 3.23-CIOSS Summary'!I13) -> 30061.77 | J24: ='Table 3.9-PARS Wst Summary'!J53 -> 30061.77 | K24: =H24-J24 -> 0
G25: rec module ---> | H25: =SUM('Table 3.25-REC Summary'!K6,'Table 3.25-REC Summary'!K10,'Table 3.25-REC Summary'!K13) -> 6238.3219 | J25: ='Table 3.9-PARS Wst Summary'!J54 -> 6238.3219 | K25: =H25-J25 -> 0
G26: Total ---> | H26: =SUM(H21:H25) -> 211638.7 | J26: =SUM(J21:J25) -> 211638.7 | K26: =H26-J26 -> 0
A28: Notes:
A29: (1) Refer to Table 3.9.
A30: (2) Refer to Table 3.10.

Sheet Table 3.9-PARS Wst Summary
A1: Table 3.9 - Cost of Wasted UAA Mail, PARS Pieces
A2: PARS Environment, FY 25
B3: Volume (000s) | D3: Cost/Piece | F3: Total Cost (000s) | H3: Frequency | J3: Cost Contribution
A4: Plant-Intercepted Non-Forwardable Waste (1)
A5: CIOSS Processing | B5: ='Table 3.24-CIOSS Detail'!E13 -> 278110.92 | C5: (6) | D5: =F5/B5 -> 0.048544837 | F5: ='Table 3.24-CIOSS Detail'!K13 -> 13500.849 | G5: (6) | H5: =B5/$B$48 -> 0.32847181 | J5: =D5*H5 -> 0.015945611
A6: AFR Finalization | B6: ='Table 3.28-REC Volume'!G13 -> 253881.9 | C6: (7) | D6: =F6/B6 -> 0 | F6: 0 | H6: =B6/$B$48 -> 0.29985535 | J6: =D6*H6 -> 0
A7: REC Site Finalization, Non-ACS Pieces | B7: ='Table 3.28-REC Volume'!H13 -> 20057.356 | C7: (7) | D7: =F7/B7 -> 0.10707332 | F7: ='Table 3.26-REC Detail NonACS'!K13 -> 2147.6078 | G7: (9) | H7: =B7/$B$48 -> 0.023689383 | J7: =D7*H7 -> 0.002536501
A8: REC Site Finalization, ACS Pieces (17) | B8: 0 | D8: 0 | F8: 0 | H8: =B8/$B$48 -> 0 | J8: =D8*H8 -> 0
A9: CIOSS Rejects - Nixie Unit Processing | B9: ='Table 3.18-Nixie UAA'!D37 -> 4171.6638 | C9: (8) | D9: =F9/B9 -> 0.018872931 | F9: ='Table 3.18-Nixie UAA'!I37 -> 78.731523 | G9: (8) | H9: =B9/$B$48 -> 0.0049270772 | J9: =D9*H9 -> 9.2988388e-05
A10: Total | B10: =B5 -> 278110.92 | D10: =F10/B10 -> 0.056550058 | F10: =SUM(F5:F9) -> 15727.189 | J10: =SUM(J5:J9) -> 0.0185751
A12: Plant-Intercepted COA Mail Waste (2)
A13: CIOSS Processing | B13: =SUM('Table 3.24-CIOSS Detail'!E6,'Table 3.24-CIOSS Detail'!E10) -> 103378.91 | C13: (6) | D13: =F13/B13 -> 0.048544837 | F13: =SUM('Table 3.24-CIOSS Detail'!K6,'Table 3.24-CIOSS Detail'!K10) -> 5018.5122 | G13: (6) | H13: =B13/$B$48 -> 0.12209897 | J13: =D13*H13 -> 0.0059272746
A14: AFR Finalization | B14: =SUM('Table 3.28-REC Volume'!G6,'Table 3.28-REC Volume'!G10) -> 94372.538 | C14: (7) | D14: =F14/B14 -> 0 | F14: 0 | H14: =B14/$B$48 -> 0.11146171 | J14: =D14*H14 -> 0
A15: REC Site Finalization, Non-ACS Pieces | B15: =SUM('Table 3.28-REC Volume'!H6) -> 502.66396 | C15: (7) | D15: =F15/B15 -> 0.10707332 | F15: =SUM('Table 3.26-REC Detail NonACS'!K6) -> 53.821899 | G15: (9) | H15: =B15/$B$48 -> 0.00059368737 | J15: =D15*H15 -> 6.3568079e-05
A16: REC Site Finalization, ACS Pieces (17) | B16: =SUM('Table 3.28-REC Volume'!H10) -> 6953.0216 | C16: (7) | D16: =F16/B16 -> 0.053536661 | F16: =SUM('Table 3.26-REC Detail NonACS'!K10) -> 372.24156 | G16: (9) | H16: =B16/$B$48 -> 0.008212089 | J16: =D16*H16 -> 0.00043964782
A17: CIOSS Rejects - CFS Unit Processing | B17: 1550.6836 | C17: (10) | D17: ='Table 3.21-CFS CIOSS Rejs'!I19 -> 0.32800427 | E17: (11) | F17: =B17*D17 -> 508.63084 | H17: =B17/$B$48 -> 0.0018314846 | J17: =D17*H17 -> 0.00060073475
A18: Total | B18: =B13 -> 103378.91 | D18: =F18/B18 -> 0.057586278 | F18: =SUM(F13:F17) -> 5953.2065 | J18: =SUM(J13:J17) -> 0.0070312253
A20: Carrier-Identified COA Mail Waste (3)
A21: Carrier Preparation | B21: ='Table 3.16-Route UAA PARS'!D108 -> 19882.087 | C21: (12) | D21: =F21/B21 -> 0.10836968 | F21: ='Table 3.16-Route UAA PARS'!J108 -> 2154.6154 | G21: (12) | H21: =B21/$B$48 -> 0.023482376 | J21: =D21*H21 -> 0.0025447776
A22: Clerk Handling - Prep for CIOSS | B22: ='Table 3.18-Nixie UAA'!D8 -> 19882.087 | C22: (13) | D22: =F22/B22 -> 0.0075934757 | F22: ='Table 3.18-Nixie UAA'!I8 -> 150.97415 | G22: (13) | H22: =B22/$B$48 -> 0.023482376 | J22: =D22*H22 -> 0.00017831285
A23: CIOSS Processing | B23: =SUM('Table 3.24-CIOSS Detail'!E21,'Table 3.24-CIOSS Detail'!E25) -> 19882.087 | C23: (6) | D23: =F23/B23 -> 0.048544837 | F23: =SUM('Table 3.24-CIOSS Detail'!K21,'Table 3.24-CIOSS Detail'!K25) -> 965.17268 | G23: (6) | H23: =B23/$B$48 -> 0.023482376 | J23: =D23*H23 -> 0.0011399481
A24: AFR Finalization | B24: =SUM('Table 3.28-REC Volume'!G21,'Table 3.28-REC Volume'!G25) -> 16567.589 | C24: (7) | D24: =F24/B24 -> 0 | F24: 0 | H24: =B24/$B$48 -> 0.019567682 | J24: =D24*H24 -> 0
A25: REC Site Finalization, Non-ACS Pieces | B25: =SUM('Table 3.28-REC Volume'!H21) -> 203.35739 | C25: (7) | D25: =F25/B25 -> 0.10707332 | F25: =SUM('Table 3.26-REC Detail NonACS'!K21) -> 21.774151 | G25: (9) | H25: =B25/$B$48 -> 0.00024018176 | J25: =D25*H25 -> 2.5717059e-05
A26: REC Site Finalization, ACS Pieces (17) | B26: =SUM('Table 3.28-REC Volume'!H25) -> 2812.9097 | C26: (7) | D26: =F26/B26 -> 0.053536661 | F26: =SUM('Table 3.26-REC Detail NonACS'!K25) -> 150.59379 | G26: (9) | H26: =B26/$B$48 -> 0.0033222771 | J26: =D26*H26 -> 0.00017786362
A27: CIOSS Rejects - CFS Unit Processing | B27: ='Table 3.21-CFS CIOSS Rejs'!B19-B17 -> 298.23131 | C27: (14) | D27: ='Table 3.21-CFS CIOSS Rejs'!I19 -> 0.32800427 | E27: (11) | F27: =B27*D27 -> 97.821142 | H27: =B27/$B$48 -> 0.00035223564 | J27: =D27*H27 -> 0.00011553479
A28: Total | B28: =B21 -> 19882.087 | D28: =F28/B28 -> 0.17809757 | F28: =SUM(F21:F27) -> 3540.9513 | J28: =SUM(J21:J27) -> 0.004182154
A30: Plant-Intercepted ACS Nixie Mail Waste (4)
A31: CIOSS Processing | B31: ='Table 3.24-CIOSS Detail'!E16 -> 29216.412 | C31: (6) | D31: =F31/B31 -> 0.048544837 | F31: ='Table 3.24-CIOSS Detail'!K16 -> 1418.3059 | G31: (6) | H31: =B31/$B$48 -> 0.034506979 | J31: =D31*H31 -> 0.0016751357
A32: AFR Finalization | B32: ='Table 3.28-REC Volume'!G16 -> 26671.078 | C32: (7) | D32: =F32/B32 -> 0 | F32: 0 | H32: =B32/$B$48 -> 0.031500732 | J32: =D32*H32 -> 0
A33: REC Site Finalization, Non-ACS Pieces | B33: 0 | D33: 0 | F33: 0 | H33: =B33/$B$48 -> 0 | J33: =D33*H33 -> 0
A34: REC Site Finalization, ACS Pieces (17) | B34: ='Table 3.28-REC Volume'!H16 -> 2107.0873 | C34: (7) | D34: =F34/B34 -> 0.053536661 | F34: =SUM('Table 3.26-REC Detail NonACS'!K16) -> 112.80642 | G34: (9) | H34: =B34/$B$48 -> 0.0024886429 | J34: =D34*H34 -> 0.00013323363
A35: CIOSS Rejects - CFS Unit Processing | B35: 438.24618 | C35: (15) | D35: ='Table 3.21-CFS CIOSS Rejs'!I76 -> 0.026418631 | E35: (11) | F35: =B35*D35 -> 11.577864 | H35: =B35/$B$48 -> 0.00051760469 | J35: =D35*H35 -> 1.3674407e-05
A36: Total | B36: =B31 -> 29216.412 | D36: =F36/B36 -> 0.05280218 | F36: =SUM(F31:F35) -> 1542.6902 | J36: =SUM(J31:J35) -> 0.0018220437
A38: Carrier-Identified ACS Nixie Mail Waste (5)
A39: Carrier Preparation | B39: ='Table 3.16-Route UAA PARS'!D101 -> 416092.91 | C39: (12) | D39: =F39/B39 -> 0.11692457 | F39: ='Table 3.16-Route UAA PARS'!J101 -> 48651.484 | G39: (12) | H39: =B39/$B$48 -> 0.49143986 | J39: =D39*H39 -> 0.057461394
A40: Clerk Handling - Prep for CIOSS | B40: ='Table 3.18-Nixie UAA'!D11 -> 416092.91 | C40: (13) | D40: =F40/B40 -> 0.0075934757 | F40: ='Table 3.18-Nixie UAA'!I11 -> 3159.5914 | G40: (13) | H40: =B40/$B$48 -> 0.49143986 | J40: =D40*H40 -> 0.0037317366
A41: CIOSS Processing | B41: =SUM('Table 3.24-CIOSS Detail'!E31,'Table 3.24-CIOSS Detail'!E37) -> 416092.91 | C41: (6) | D41: =F41/B41 -> 0.022011743 | F41: =SUM('Table 3.24-CIOSS Detail'!K31,'Table 3.24-CIOSS Detail'!K37) -> 9158.93 | G41: (6) | H41: =B41/$B$48 -> 0.49143986 | J41: =D41*H41 -> 0.010817448
A42: AFR Finalization | B42: =SUM('Table 3.28-REC Volume'!G31,'Table 3.28-REC Volume'!G37) -> 346726.99 | C42: (7) | D42: =F42/B42 -> 0 | F42: 0 | H42: =B42/$B$48 -> 0.40951302 | J42: =D42*H42 -> 0
A43: REC Site Finalization, Non-ACS Pieces | B43: 0 | D43: 0 | F43: 0 | H43: =B43/$B$48 -> 0 | J43: =D43*H43 -> 0
A44: REC Site Finalization, ACS Pieces (17) | B44: =SUM('Table 3.28-REC Volume'!H31,'Table 3.28-REC Volume'!H37) -> 63124.527 | C44: (7) | D44: =F44/B44 -> 0.053536661 | F44: =SUM('Table 3.26-REC Detail NonACS'!K31,'Table 3.26-REC Detail NonACS'!K37) -> 3379.4764 | G44: (9) | H44: =B44/$B$48 -> 0.074555245 | J44: =D44*H44 -> 0.0039914388
...

Sheet Table 3.10-NonPARS Wst Summary
A1: Table 3.10 - Cost of Wasted UAA Mail, Non-PARS Pieces
A2: PARS Environment, FY 25
B3: Volume (000s) | D3: Cost/Piece | F3: Total Cost (000s) | H3: Frequency | J3: Cost Contribution
A4: Delivery Unit Waste (1)
A5: Carrier Preparation | B5: ='Table 3.15-Route UAA NoPARS'!D111+'Table 3.16-Route UAA PARS'!D111 -> 1368978.5 | C5: (4) | D5: =F5/B5 -> 0.039956754 | F5: ='Table 3.15-Route UAA NoPARS'!J111+'Table 3.16-Route UAA PARS'!J111 -> 54699.939 | G5: (4) | H5: =B5/$B$20 -> 0.94256638 | J5: =D5*H5 -> 0.037661893
A6: Clerk Handling - Verifying Waste | B6: =SUM('Table 3.18-Nixie UAA'!D20,'Table 3.18-Nixie UAA'!D29) -> 1368978.5 | C6: (5) | D6: =F6/B6 -> 0.021362779 | F6: =SUM('Table 3.18-Nixie UAA'!I20,'Table 3.18-Nixie UAA'!I29) -> 29245.187 | G6: (5) | H6: =B6/$B$20 -> 0.94256638 | J6: =D6*H6 -> 0.020135838
A7: Total | B7: =B5 -> 1368978.5 | D7: =F7/B7 -> 0.061319533 | F7: =SUM(F5:F6) -> 83945.125 | J7: =SUM(J5:J6) -> 0.057797731
A9: CFS Unit COA Mail Waste (2)
